<?xml version="1.0"?>
<robot name="car" >


    <material name="Black">
        <color rgba="0.0 0.0 0.0 1.0"/>
    </material>
    <material name="Red">
        <color rgba="0.8 0.0 0.0 1.0"/>
    </material>
    <material name="White">
        <color rgba="1.0 1.0 1.0 1.0"/>
    </material>
    <material name="Blue">
        <color rgba="0.0 0.0 0.8 1.0"/>
    </material>
    <material name="yellow">
        <color rgba="1.0 1.0 0.0 1.0"/>
    </material>

    <link name="floor">
        <visual>
            <geometry>
                <box size="0 0 0"/>
            </geometry>
            <origin rpy="0 0 0" xyz="0 0 0" />
        </visual>
    </link>


    <link name="base_link">
        <visual>
            <geometry>
                <box size="2 1 0.05"/>
            </geometry>
            <origin rpy="0 0 0" xyz="0 0 0.08"/>
            <material name="White"/>
        </visual>
    </link>
    <joint name="base" type="floating">
        <parent link="floor"/>
        <child link="base_link"/>
        <origin rpy="0 0 0" xyz="0 0 0"/>
        <limit effort="100" velocity="100"/>
    </joint>

    <link name="front_right">
        <visual>
            <geometry>
                <cylinder length="0.1" radius="0.08"/>
            </geometry>
            <origin rpy="1.57 0 0" xyz="0 0.05 0"/>
            <material name="Black">
                <color rgba="0.0 0.0 0.0 1.0"/>
            </material>
        </visual>
    </link>
    <joint name="front_right_joint" type="revolute">
        <parent link="base_link"/>
        <child link="front_right"/>
        <origin rpy="0 0 0" xyz="-0.5 0.5 0.08"/>
        <axis rpy="0  0" xyz="0 0 1"/>
        <limit effort="100" lower="-0.5" upper="0.5"  velocity="100"/>
        <!-- <joint_properties damping="0.0" friction="0.0"/> -->
    </joint>

    

    <link name="front_left">
        <visual>
            <geometry>
                <cylinder length="0.1" radius="0.08"/>
            </geometry>
            <origin rpy="1.57 0 0" xyz="0 -0.05 0"/>
            <material name="Black"/>
        </visual>
    </link>
    <joint name="front_left_joint" type="revolute">
        <parent link="base_link"/>
        <child link="front_left"/>
        <origin rpy="0 0 0" xyz="-0.5 -0.5 0.08"/>
        <axis rpy="0  0" xyz="0 0 1"/>
        <limit effort="100" lower="-0.5" upper="0.5" velocity="100"/>
        <!-- <joint_properties damping="0.0" friction="0.0"/> -->
    </joint>



    <link name="back_right">
        <visual>
            <geometry>
                <cylinder length="0.1" radius="0.08"/>
            </geometry>
            <origin rpy="1.57 0 0" xyz="0 0.05 0"/>
            <material name="Black"/>
        </visual>
    </link>
    <joint name="back_right_joint" type="continuous">
        <parent link="base_link"/>
        <child link="back_right"/>
        <origin rpy="0 0 0" xyz="0.5 0.5 0.04"/>
        <axis rpy="0  0" xyz="0 1 0"/>
        <limit effort="100" velocity="100"/>
        <!-- <joint_properties damping="0.0" friction="0.0"/> -->
    </joint>




    <link name="back_left">
        <visual>
            <geometry>
                <cylinder length="0.1" radius="0.08"/>
            </geometry>
            <origin rpy="1.57 0 0" xyz="0 -0.05 0"/>
            <material name="Black"/>
        </visual>
    </link>
    <joint name="back_left_joint" type="continuous">
        <parent link="base_link"/>
        <child link="back_left"/>
        <origin rpy="0 0 0" xyz="0.5 -0.5 0.04"/>
        <axis rpy="0  0" xyz="0 1 0"/>
        <limit effort="100" velocity="100"/>
        <!-- <joint_properties damping="0.0" friction="0.0"/> -->
    </joint>
</robot>
